<?xml version="1.0"?>
<robot xmlns:xacro="http://www.ros.org/wiki/xacro" name="robot2">

    <xacro:include filename="inertia.xacro"/>

    <material name="white">
        <color rgba="1 1 1 1" />
    </material>

    <material name="orange">
        <color rgba="1 0.3 0.1 1"/>
    </material>

    <material name="blue">
        <color rgba="0.2 0.2 1 1"/>
    </material>

    <material name="black">
        <color rgba="0 0 0 1"/>
    </material>

    <!-- BASE LINK -->

    <link name="base_link2">
    </link>


    <!-- CHASSIS LINK -->

    <joint name="/robot2/chassis_joint" type="fixed">
        <parent link="base_link2"/>
        <child link="/robot2/chassis"/>
        <origin xyz="0 0 0.02"/>
    </joint>

    <link name="/robot2/chassis">
        <visual>
            <origin xyz="0.075 0 0.1"/>
            <geometry>
                <box size="0.15 0.15 0.2"/>
            </geometry>
            <material name="orange"/>
        </visual>
        <collision>
            <origin xyz="0.075 0 0.1"/>
            <geometry>
                <box size="0.15 0.15 0.2"/>
            </geometry>
        </collision>
        <xacro:inertial_box mass="1" x="0.15" y="0.15" z="0.3">
            <origin xyz="0.075 0 0.1" rpy="0 0 0"/>
        </xacro:inertial_box>
    </link>
    <gazebo reference="/robot2/chassis">
        <material>Gazebo/Orange</material>
    </gazebo>

    <!-- LEFT WHEEL LINK -->

    <joint name="/robot2/left_wheel_joint" type="continuous">
        <parent link="/robot2/chassis"/>
        <child link="/robot2/left_wheel"/>
        <origin xyz="0.115 0.085 0" rpy="-${pi/2} 0 0" />
        <axis xyz="0 0 1"/>
    </joint>

    <link name="/robot2/left_wheel">
        <visual>
            <geometry>
                <cylinder radius="0.035" length="0.02"/>
            </geometry>
            <material name="white"/>
        </visual>
        <collision>
            <geometry>
                <cylinder radius="0.035" length="0.02"/>
            </geometry>
        </collision>
        <xacro:inertial_cylinder mass="0.05" length="0.02" radius="0.035">
            <origin xyz="0 0 0" rpy="0 0 0"/>
        </xacro:inertial_cylinder>
    </link>

    <gazebo reference="/robot2/left_wheel">
        <material>Gazebo/White</material>
    </gazebo>

    <!-- RIGHT WHEEL LINK -->

    <joint name="/robot2/right_wheel_joint" type="continuous">
        <parent link="/robot2/chassis"/>
        <child link="/robot2/right_wheel"/>
        <origin xyz="0.115 -0.085 0" rpy="${pi/2} 0 0" />
        <axis xyz="0 0 -1"/>
    </joint>

    <link name="/robot2/right_wheel">
        <visual>
            <geometry>
                <cylinder radius="0.035" length="0.02"/>
            </geometry>
            <material name="white"/>
        </visual>
        <collision>
            <geometry>
                <cylinder radius="0.035" length="0.02"/>
            </geometry>
        </collision>
        <xacro:inertial_cylinder mass="0.05" length="0.02" radius="0.035">
            <origin xyz="0 0 0" rpy="0 0 0"/>
        </xacro:inertial_cylinder>
    </link>

    <gazebo reference="/robot2/right_wheel">
        <material>Gazebo/White</material>
    </gazebo>

    <!-- DIFF DRIVE GAZEBO PLUGIN -->
    <gazebo>
        <plugin name="diff_drive_robot2" filename="libgazebo_ros_diff_drive.so">
            
            <!-- Wheel Information -->
            <left_joint>/robot2/left_wheel_joint</left_joint>
            <right_joint>/robot2/right_wheel_joint</right_joint>
            <wheel_separation>0.17</wheel_separation>
            <wheel_diameter>0.07</wheel_diameter>
    
            <!-- Limits -->
            <max_wheel_torque>200</max_wheel_torque>
            <max_wheel_acceleration>10.0</max_wheel_acceleration>
    
            <!-- Output -->
            <odometry_frame>odom</odometry_frame>
            <robot_base_frame>base_link2</robot_base_frame>
    
            <publish_odom>true</publish_odom>
            <publish_odom_tf>true</publish_odom_tf>
            <publish_wheel_tf>true</publish_wheel_tf>
    
            <!-- ROS namespace and remapping -->
            <ros>
                <namespace>/robot2</namespace>
                <remapping>cmd_vel:=/robot2/cmd_vel</remapping>
        
            </ros>
        </plugin>
    </gazebo>

    <!-- LIDAR LINK -->
    <joint name="/robot2/laser_joint" type="fixed">
        <parent link="/robot2/chassis"/>
        <child link="/robot2/laser_frame"/>
        <origin xyz="0.1 0 0.200" rpy="0 0 0"/>
    </joint>

    <link name="/robot2/laser_frame">
        <visual>
            <geometry>
                <cylinder radius="0.03" length="0.04"/>
            </geometry>
            <material name="black"/>
        </visual>
        <collision>
            <geometry>
                <cylinder radius="0.03" length="0.04"/>
            </geometry>
        </collision>
        <xacro:inertial_cylinder mass="0.1" length="0.04" radius="0.05">
            <origin xyz="0 0 0" rpy="0 0 0"/>
        </xacro:inertial_cylinder>
    </link>

    <gazebo reference="/robot2/laser_frame">
        <material>Gazebo/Black</material>
        <sensor name="laser" type="ray">
            <pose> 0 0 0 0 0 0 </pose>
            <visualize>true</visualize>
            <update_rate>10</update_rate>
            <ray>
                <scan>
                    <horizontal>
                        <samples>360</samples>
                        <min_angle>-3.14</min_angle>
                        <max_angle>3.14</max_angle>
                    </horizontal>
                </scan>
                <range>
                    <min>0.3</min>
                    <max>4</max>
                </range>
            </ray>
            <plugin name="laser_controller_robot2" filename="libgazebo_ros_ray_sensor.so">
                <ros>
                    <argument>~/out:=scan_robot2</argument>
                </ros>
                <output_type>sensor_msgs/LaserScan</output_type>
                <frame_name>laser_frame_robot2</frame_name>
            </plugin>
        </sensor>
    </gazebo>


    <!-- CASTER WHEEL LINK -->

    <joint name="/robot2/caster_wheel_joint_cylinder" type="fixed">
        <parent link="/robot2/chassis"/>
        <child link="/robot2/caster_wheel_cylinder"/>
        <origin xyz="0.02 0 0"/>
    </joint>


    <link name="/robot2/caster_wheel_cylinder">
        <visual>
            <geometry>
                <cylinder radius="0.01" length="0.05"/>
            </geometry>
            <material name="black"/>
        </visual>
        <collision>
            <geometry>
                <cylinder radius="0.01" length="0.05"/>
            </geometry>
        </collision>
        <xacro:inertial_cylinder mass="0.5" length="0.05" radius="0.01">
            <origin xyz="0 0 0" rpy="0 0 0"/>
        </xacro:inertial_cylinder>
    </link>

    <gazebo reference="/robot2/caster_wheel_cylinder">
        <material>Gazebo/Black</material>
        
    </gazebo>

    <joint name="/robot2/caster_wheel_joint_sphere" type="fixed">
        <parent link="/robot2/chassis"/>
        <child link="/robot2/caster_wheel_sphere"/>
        <origin xyz="0.02 0 -0.025"/>
    </joint>


    <link name="/robot2/caster_wheel_sphere">
        <visual>
            <geometry>
                <sphere radius="0.01"/>
            </geometry>
            <material name="white"/>
        </visual>
        <collision>
            <geometry>
                <sphere radius="0.01"/>
            </geometry>
        </collision>
        <xacro:inertial_sphere mass="0.5" radius="0.01">
            <origin xyz="0 0 0" rpy="0 0 0"/>
        </xacro:inertial_sphere>
    </link>

    <gazebo reference="/robot2/caster_wheel_sphere">
        <material>Gazebo/White</material>
        <mu1 value = "0.001"/>
        <mu2 value = "0.001"/>
    </gazebo>


    
    
</robot>