<?xml version="1.0"?>
<robot xmlns:xacro="http://www.ros.org/wiki/xacro" name="robot">

    <xacro:macro name="inertial_sphere" params="mass radius *origin">
        <inertial>
            <xacro:insert_block name="origin"/>
            <mass value="${mass}" />
            <inertia ixx="${(2/5) * mass * (radius*radius)}" ixy="0.0" ixz="0.0"
                    iyy="${(2/5) * mass * (radius*radius)}" iyz="0.0"
                    izz="${(2/5) * mass * (radius*radius)}" />
        </inertial>
    </xacro:macro>

    <xacro:macro name="inertial_box" params="mass x y z *origin">
        <inertial>
            <xacro:insert_block name="origin"/>
            <mass value="${mass}" />
            <inertia ixx="${(1/12) * mass * (y*y+z*z)}" ixy="0.0" ixz="0.0"
                    iyy="${(1/12) * mass * (x*x+z*z)}" iyz="0.0"
                    izz="${(1/12) * mass * (x*x+y*y)}" />
        </inertial>
    </xacro:macro>

    <xacro:macro name="inertial_cylinder" params="mass length radius *origin">
        <inertial>
            <xacro:insert_block name="origin"/>
            <mass value="${mass}" />
            <inertia ixx="${(1/12) * mass * (3*radius*radius + length*length)}" ixy="0.0" ixz="0.0"
                    iyy="${(1/12) * mass * (3*radius*radius + length*length)}" iyz="0.0"
                    izz="${(1/2) * mass * (radius*radius)}" />
        </inertial>
    </xacro:macro>

    <material name="white">
        <color rgba="1 1 1 1" />
    </material>

    <material name="orange">
        <color rgba="1 0.3 0.1 1"/>
    </material>

    <material name="blue">
        <color rgba="0.2 0.2 1 1"/>
    </material>

    <material name="black">
        <color rgba="0 0 0 1"/>
    </material>

    <xacro:macro name="robot_with_namespace" params="namespace">

        <!-- BASE LINK -->
        <link name="${arg namespace}/base_link"/>

        <!-- CHASSIS LINK -->
        <joint name="${arg namespace}/chassis_joint" type="fixed">
            <parent link="${arg namespace}/base_link"/>
            <child link="${arg namespace}/chassis"/>
            <origin xyz="-0.05 0 0"/>
        </joint>

        <link name="${arg namespace}/chassis">
            <visual>
                <origin xyz="0.075 0 0.1"/>
                <geometry>
                    <box size="0.15 0.15 0.2"/>
                </geometry>
                <material name="blue"/>
            </visual>
            <collision>
                <origin xyz="0.075 0 0.1"/>
                <geometry>
                    <box size="0.15 0.15 0.2"/>
                </geometry>
            </collision>
            <xacro:inertial_box mass="1" x="0.15" y="0.15" z="0.3">
                <origin xyz="0.075 0 0.1" rpy="0 0 0"/>
            </xacro:inertial_box>
        </link>
        <gazebo reference="${arg namespace}/chassis">
            <material>Gazebo/Blue</material>
        </gazebo>

        <!-- LEFT WHEEL LINK -->
        <joint name="${arg namespace}/left_wheel_joint" type="continuous">
            <parent link="${arg namespace}/chassis"/>
            <child link="${arg namespace}/left_wheel"/>
            <origin xyz="0.115 0.085 0" rpy="-${pi/2} 0 0" />
            <axis xyz="0 0 1"/>
        </joint>

        <link name="${arg namespace}/left_wheel">
            <visual>
                <geometry>
                    <cylinder radius="0.035" length="0.02"/>
                </geometry>
                <material name="white"/>
            </visual>
            <collision>
                <geometry>
                    <cylinder radius="0.035" length="0.02"/>
                </geometry>
            </collision>
            <xacro:inertial_cylinder mass="0.05" length="0.02" radius="0.035">
                <origin xyz="0 0 0" rpy="0 0 0"/>
            </xacro:inertial_cylinder>
        </link>

        <gazebo reference="${arg namespace}/left_wheel">
            <material>Gazebo/White</material>
        </gazebo>

        <!-- RIGHT WHEEL LINK -->
        <joint name="${arg namespace}/right_wheel_joint" type="continuous">
            <parent link="${arg namespace}/chassis"/>
            <child link="${arg namespace}/right_wheel"/>
            <origin xyz="0.115 -0.085 0" rpy="${pi/2} 0 0" />
            <axis xyz="0 0 -1"/>
        </joint>

        <link name="${arg namespace}/right_wheel">
            <visual>
                <geometry>
                    <cylinder radius="0.035" length="0.02"/>
                </geometry>
                <material name="white"/>
            </visual>
            <collision>
                <geometry>
                    <cylinder radius="0.035" length="0.02"/>
                </geometry>
            </collision>
            <xacro:inertial_cylinder mass="0.05" length="0.02" radius="0.035">
                <origin xyz="0 0 0" rpy="0 0 0"/>
            </xacro:inertial_cylinder>
        </link>

        <gazebo reference="${arg namespace}/right_wheel">
            <material>Gazebo/White</material>
        </gazebo>

        <!-- CASTER WHEEL LINK -->
        <joint name="${arg namespace}/caster_wheel_joint_cylinder" type="fixed">
            <parent link="${arg namespace}/chassis"/>
            <child link="${arg namespace}/caster_wheel_cylinder"/>
            <origin xyz="0.02 0 0"/>
        </joint>

        <link name="${arg namespace}/caster_wheel_cylinder">
            <visual>
                <geometry>
                    <cylinder radius="0.01" length="0.05"/>
                </geometry>
                <material name="black"/>
            </visual>
            <collision>
                <geometry>
                    <cylinder radius="0.01" length="0.05"/>
                </geometry>
            </collision>
            <xacro:inertial_cylinder mass="0.5" length="0.05" radius="0.01">
                <origin xyz="0 0 0" rpy="0 0 0"/>
            </xacro:inertial_cylinder>
        </link>

        <gazebo reference="${arg namespace}/caster_wheel_cylinder">
            <material>Gazebo/Black</material>
        </gazebo>

        <joint name="${arg namespace}/caster_wheel_joint_sphere" type="fixed">
            <parent link="${arg namespace}/chassis"/>
            <child link="${arg namespace}/caster_wheel_sphere"/>
            <origin xyz="0.02 0 -0.025"/>
        </joint>

        <link name="${arg namespace}/caster_wheel_sphere">
            <visual>
                <geometry>
                    <sphere radius="0.01"/>
                </geometry>
                <material name="white"/>
            </visual>
            <collision>
                <geometry>
                    <sphere radius="0.01"/>
                </geometry>
            </collision>
            <xacro:inertial_sphere mass="0.5" radius="0.01">
                <origin xyz="0 0 0" rpy="0 0 0"/>
            </xacro:inertial_sphere>
        </link>

        <gazebo reference="${arg namespace}/caster_wheel_sphere">
            <material>Gazebo/White</material>
            <mu1 value = "0.001"/>
            <mu2 value = "0.001"/>
        </gazebo>

        <!-- Lidar Link -->
        <joint name="${arg namespace}/laser_joint" type="fixed">
            <parent link="${arg namespace}/chassis"/>
            <child link="${arg namespace}/laser_frame"/>
            <origin xyz="0.1 0 0.200" rpy="0 0 0"/>
        </joint>

        <link name="${arg namespace}/laser_frame">
            <visual>
                <geometry>
                    <cylinder radius="0.03" length="0.04"/>
                </geometry>
                <material name="white"/>
            </visual>
            <collision>
                <geometry>
                    <cylinder radius="0.03" length="0.04"/>
                </geometry>
            </collision>
            <xacro:inertial_cylinder mass="0.1" radius="0.03" length="0.04">
                <origin xyz="0 0 0" rpy="0 0 0"/>
            </xacro:inertial_cylinder>
        </link>

        <gazebo reference="${arg namespace}/laser_frame">
            <material>Gazebo/White</material>
        </gazebo>

    </xacro:macro>

    <!-- Define robots with different namespaces -->
    <!-- <xacro:robot_with_namespace namespace="robot1" />
    <xacro:robot_with_namespace namespace="robot2" /> -->
</robot>
